SampleInputOutputFiles/set2/input /exampleOrders.csv
21,Jane,1623239790,BUY,98,8312
22,Chris,1623239792,BUY,98,8300
23,Willium,1623239793,SELL,38,8000
24,Christina,1623239794,BUY,100,9000
25,Sravan,1623239795,BUY,38,8500
26,Arun,1623239796,SELL,38,8600
27,Kiran,1623239796,SELL,38,8650
